2021-07-24 18:38:14,356 INFO: Microblog startup [in C:\Users\user\Desktop\Flask\Microblog\app\__init__.py:44]
2021-07-24 18:43:48,676 ERROR: Exception on /edit_profile [POST] [in C:\Users\user\Desktop\Flask\Microblog\venv\lib\site-packages\flask\app.py:1454]
Traceback (most recent call last):
  File "C:\Users\user\Desktop\Flask\Microblog\venv\lib\site-packages\sqlalchemy\engine\base.py", line 1771, in _execute_context
    self.dialect.do_execute(
  File "C:\Users\user\Desktop\Flask\Microblog\venv\lib\site-packages\sqlalchemy\engine\default.py", line 717, in do_execute
    cursor.execute(statement, parameters)
sqlite3.IntegrityError: UNIQUE constraint failed: user.username

The above exception was the direct cause of the following exception:

Traceback (most recent call last):
  File "C:\Users\user\Desktop\Flask\Microblog\venv\lib\site-packages\flask\app.py", line 2070, in wsgi_app
    response = self.full_dispatch_request()
  File "C:\Users\user\Desktop\Flask\Microblog\venv\lib\site-packages\flask\app.py", line 1515, in full_dispatch_request
    rv = self.handle_user_exception(e)
  File "C:\Users\user\Desktop\Flask\Microblog\venv\lib\site-packages\flask\app.py", line 1513, in full_dispatch_request
    rv = self.dispatch_request()
  File "C:\Users\user\Desktop\Flask\Microblog\venv\lib\site-packages\flask\app.py", line 1499, in dispatch_request
    return self.ensure_sync(self.view_functions[rule.endpoint])(**req.view_args)
  File "C:\Users\user\Desktop\Flask\Microblog\venv\lib\site-packages\flask_login\utils.py", line 272, in decorated_view
    return func(*args, **kwargs)
  File "C:\Users\user\Desktop\Flask\Microblog\app\routes.py", line 98, in edit_profile
    db.session.commit()
  File "<string>", line 2, in commit
  File "C:\Users\user\Desktop\Flask\Microblog\venv\lib\site-packages\sqlalchemy\orm\session.py", line 1428, in commit
    self._transaction.commit(_to_root=self.future)
  File "C:\Users\user\Desktop\Flask\Microblog\venv\lib\site-packages\sqlalchemy\orm\session.py", line 829, in commit
    self._prepare_impl()
  File "C:\Users\user\Desktop\Flask\Microblog\venv\lib\site-packages\sqlalchemy\orm\session.py", line 808, in _prepare_impl
    self.session.flush()
  File "C:\Users\user\Desktop\Flask\Microblog\venv\lib\site-packages\sqlalchemy\orm\session.py", line 3298, in flush
    self._flush(objects)
  File "C:\Users\user\Desktop\Flask\Microblog\venv\lib\site-packages\sqlalchemy\orm\session.py", line 3438, in _flush
    transaction.rollback(_capture_exception=True)
  File "C:\Users\user\Desktop\Flask\Microblog\venv\lib\site-packages\sqlalchemy\util\langhelpers.py", line 70, in __exit__
    compat.raise_(
  File "C:\Users\user\Desktop\Flask\Microblog\venv\lib\site-packages\sqlalchemy\util\compat.py", line 207, in raise_
    raise exception
  File "C:\Users\user\Desktop\Flask\Microblog\venv\lib\site-packages\sqlalchemy\orm\session.py", line 3398, in _flush
    flush_context.execute()
  File "C:\Users\user\Desktop\Flask\Microblog\venv\lib\site-packages\sqlalchemy\orm\unitofwork.py", line 456, in execute
    rec.execute(self)
  File "C:\Users\user\Desktop\Flask\Microblog\venv\lib\site-packages\sqlalchemy\orm\unitofwork.py", line 630, in execute
    util.preloaded.orm_persistence.save_obj(
  File "C:\Users\user\Desktop\Flask\Microblog\venv\lib\site-packages\sqlalchemy\orm\persistence.py", line 234, in save_obj
    _emit_update_statements(
  File "C:\Users\user\Desktop\Flask\Microblog\venv\lib\site-packages\sqlalchemy\orm\persistence.py", line 998, in _emit_update_statements
    c = connection._execute_20(
  File "C:\Users\user\Desktop\Flask\Microblog\venv\lib\site-packages\sqlalchemy\engine\base.py", line 1583, in _execute_20
    return meth(self, args_10style, kwargs_10style, execution_options)
  File "C:\Users\user\Desktop\Flask\Microblog\venv\lib\site-packages\sqlalchemy\sql\elements.py", line 323, in _execute_on_connection
    return connection._execute_clauseelement(
  File "C:\Users\user\Desktop\Flask\Microblog\venv\lib\site-packages\sqlalchemy\engine\base.py", line 1452, in _execute_clauseelement
    ret = self._execute_context(
  File "C:\Users\user\Desktop\Flask\Microblog\venv\lib\site-packages\sqlalchemy\engine\base.py", line 1814, in _execute_context
    self._handle_dbapi_exception(
  File "C:\Users\user\Desktop\Flask\Microblog\venv\lib\site-packages\sqlalchemy\engine\base.py", line 1995, in _handle_dbapi_exception
    util.raise_(
  File "C:\Users\user\Desktop\Flask\Microblog\venv\lib\site-packages\sqlalchemy\util\compat.py", line 207, in raise_
    raise exception
  File "C:\Users\user\Desktop\Flask\Microblog\venv\lib\site-packages\sqlalchemy\engine\base.py", line 1771, in _execute_context
    self.dialect.do_execute(
  File "C:\Users\user\Desktop\Flask\Microblog\venv\lib\site-packages\sqlalchemy\engine\default.py", line 717, in do_execute
    cursor.execute(statement, parameters)
sqlalchemy.exc.IntegrityError: (sqlite3.IntegrityError) UNIQUE constraint failed: user.username
[SQL: UPDATE user SET username=?, about_me=? WHERE user.id = ?]
[parameters: ('dilshad', '', 2)]
(Background on this error at: https://sqlalche.me/e/14/gkpj)
2021-07-25 10:26:50,191 INFO: Microblog startup [in C:\Users\user\Desktop\Flask\Microblog\app\__init__.py:44]
